Workbook

Sheet Summary
A1: SEC Form 8-K incidents vs VCDB
A2: Hand-coded 8-K cybersecurity incident disclosures, Dec 18, 2023 – Dec 31, 2025, compared with VCDB events under the hand campaign rule (B). Black = formulas over the Incidents sheet; blue = values from the repo results.
A4: Screening
A5: Filings returned by EDGAR search | B5: =COUNTA(Screening!A2:A1000) -> 206
A6: Companies | B6: 139
A7: Incident reports (first filing) | B7: =COUNTIF(Screening!F2:F1000,"incident*") -> 68
A8: Update filings | B8: =COUNTIF(Screening!F2:F1000,"update*") -> 26
A9: Excluded (not incident reports) | B9: =COUNTIF(Screening!F2:F1000,"excluded*") -> 112
A10: Incidents ever filed under Item 1.05 | B10: =COUNTIF(Incidents!F2:F69,"Y") -> 40
A11: Events after merging CDK dealers | B11: =COUNTIF(Incidents!K2:K69,"Y") -> 65
A13: Table VI — SEC events vs VCDB events (hand rule)
A14: Measure | B14: SEC count | C14: SEC base | D14: SEC % | E14: VCDB count | F14: VCDB base | G14: VCDB % | H14: Fisher exact p
A15: Environment stated | B15: =COUNTIFS(Incidents!K2:K69,"Y",Incidents!G2:G69,"<>UND") -> 22 | C15: =COUNTIF(Incidents!K2:K69,"Y") -> 65 | D15: =IF(C15=0,0,B15/C15) -> 0.33846154 | E15: 56 | F15: 201 | G15: =IF(F15=0,0,E15/F15) -> 0.27860697 | H15: 0.35
A16: Cloud, share of those | B16: =COUNTIFS(Incidents!K2:K69,"Y",Incidents!G2:G69,"CLOUD") -> 4 | C16: =B15 -> 22 | D16: =IF(C16=0,0,B16/C16) -> 0.18181818 | E16: 36 | F16: 56 | G16: =IF(F16=0,0,E16/F16) -> 0.64285714 | H16: 0.00033
A17: Root cause stated | B17: =COUNTIFS(Incidents!K2:K69,"Y",Incidents!H2:H69,"<>OTHER") -> 11 | C17: =C15 -> 65 | D17: =IF(C17=0,0,B17/C17) -> 0.16923077 | E17: 108 | F17: 201 | G17: =IF(F17=0,0,E17/F17) -> 0.53731343 | H17: 1.3e-07
A18: Misconfiguration | B18: =COUNTIFS(Incidents!K2:K69,"Y",Incidents!H2:H69,"MISCONFIG") -> 0 | C18: =C15 -> 65 | D18: =IF(C18=0,0,B18/C18) -> 0 | E18: 45 | F18: 201 | G18: =IF(F18=0,0,E18/F18) -> 0.2238806 | H18: 1.5e-06
A20: VCDB causes come partly from curators' structured codes (drawing on press coverage); SEC causes come from the filing text alone.
A22: Root causes, SEC events
A23: Root cause | B23: Primary order | C23: Alternative order
A24: PHYSICAL | B24: =COUNTIFS(Incidents!K2:K69,"Y",Incidents!H2:H69,A24) -> 0 | C24: =COUNTIFS(Incidents!K2:K69,"Y",Incidents!I2:I69,A24) -> 0
A25: THIRD_PARTY | B25: =COUNTIFS(Incidents!K2:K69,"Y",Incidents!H2:H69,A25) -> 7 | C25: =COUNTIFS(Incidents!K2:K69,"Y",Incidents!I2:I69,A25) -> 4
A26: INSIDER | B26: =COUNTIFS(Incidents!K2:K69,"Y",Incidents!H2:H69,A26) -> 3 | C26: =COUNTIFS(Incidents!K2:K69,"Y",Incidents!I2:I69,A26) -> 3
A27: UNPATCHED | B27: =COUNTIFS(Incidents!K2:K69,"Y",Incidents!H2:H69,A27) -> 1 | C27: =COUNTIFS(Incidents!K2:K69,"Y",Incidents!I2:I69,A27) -> 2
A28: MISCONFIG | B28: =COUNTIFS(Incidents!K2:K69,"Y",Incidents!H2:H69,A28) -> 0 | C28: =COUNTIFS(Incidents!K2:K69,"Y",Incidents!I2:I69,A28) -> 0
A29: CREDENTIAL | B29: =COUNTIFS(Incidents!K2:K69,"Y",Incidents!H2:H69,A29) -> 0 | C29: =COUNTIFS(Incidents!K2:K69,"Y",Incidents!I2:I69,A29) -> 2
A30: OTHER | B30: =COUNTIFS(Incidents!K2:K69,"Y",Incidents!H2:H69,A30) -> 54 | C30: =COUNTIFS(Incidents!K2:K69,"Y",Incidents!I2:I69,A30) -> 54
A31: Total | B31: =SUM(B24:B30) -> 65 | C31: =SUM(C24:C30) -> 65
A33: Environment × root cause, SEC events
A34: Root cause | B34: CLOUD | C34: ONPREM | D34: UND
A35: THIRD_PARTY | B35: =COUNTIFS(Incidents!K2:K69,"Y",Incidents!G2:G69,"CLOUD",Incidents!H2:H69,$A35) -> 1 | C35: =COUNTIFS(Incidents!K2:K69,"Y",Incidents!G2:G69,"ONPREM",Incidents!H2:H69,$A35) -> 1 | D35: =COUNTIFS(Incidents!K2:K69,"Y",Incidents!G2:G69,"UND",Incidents!H2:H69,$A35) -> 5
A36: INSIDER | B36: =COUNTIFS(Incidents!K2:K69,"Y",Incidents!G2:G69,"CLOUD",Incidents!H2:H69,$A36) -> 0 | C36: =COUNTIFS(Incidents!K2:K69,"Y",Incidents!G2:G69,"ONPREM",Incidents!H2:H69,$A36) -> 0 | D36: =COUNTIFS(Incidents!K2:K69,"Y",Incidents!G2:G69,"UND",Incidents!H2:H69,$A36) -> 3
A37: UNPATCHED | B37: =COUNTIFS(Incidents!K2:K69,"Y",Incidents!G2:G69,"CLOUD",Incidents!H2:H69,$A37) -> 0 | C37: =COUNTIFS(Incidents!K2:K69,"Y",Incidents!G2:G69,"ONPREM",Incidents!H2:H69,$A37) -> 0 | D37: =COUNTIFS(Incidents!K2:K69,"Y",Incidents!G2:G69,"UND",Incidents!H2:H69,$A37) -> 1
A38: OTHER | B38: =COUNTIFS(Incidents!K2:K69,"Y",Incidents!G2:G69,"CLOUD",Incidents!H2:H69,$A38) -> 3 | C38: =COUNTIFS(Incidents!K2:K69,"Y",Incidents!G2:G69,"ONPREM",Incidents!H2:H69,$A38) -> 17 | D38: =COUNTIFS(Incidents!K2:K69,"Y",Incidents!G2:G69,"UND",Incidents!H2:H69,$A38) -> 34

Sheet Incidents
A1: # | B1: Company | C1: First filing date | D1: Accession | E1: Item (first filing) | F1: Ever Item 1.05 | G1: Environment | H1: Root cause | I1: Root cause (alt. order) | J1: Campaign | K1: Counts as event | L1: Basis (from filing text) | M1: Cost low (USD) | N1: Cost high (USD) | O1: Notes | P1: Filing URL
A2: 1 | B2: V F CORP | C2: 2023-12-18 | D2: 0000950123-23-011228 | E2: 1.05 | F2: Y | G2: UND | H2: OTHER | I2: OTHER | K2: Y | L2: threat actor encrypted some IT systems and stole data; hosting not stated | P2: https://www.sec.gov/Archives/edgar/data/103379/000095012323011228/d659095d8k.htm
A3: 2 | B3: First American Financial Corp | C3: 2023-12-22 | D3: 0000950170-23-072513 | E3: 1.05 | F3: Y | G3: UND | H3: OTHER | I3: OTHER | K3: Y | L3: unauthorized activity on IT systems; isolated systems from the Internet | O3: one-time expenses, amount not stated | P3: https://www.sec.gov/Archives/edgar/data/1472787/000095017023072513/faf-20231220.htm
A4: 3 | B4: loanDepot, Inc. | C4: 2024-01-08 | D4: 0001831631-24-000004 | E4: 8.01 | F4: N | G4: UND | H4: OTHER | I4: OTHER | K4: Y | L4: unauthorized access to systems and encryption of data | M4: 12000000 | N4: 17000000 | O4: Q1 2024 expenses net of insurance | P4: https://www.sec.gov/Archives/edgar/data/1831631/000183163124000004/ldi-20240104.htm
A5: 4 | B5: Fidelity National Financial, Inc. | C5: 2024-01-09 | D5: 0001331875-24-000005 | E5: 8.01 | F5: N | G5: ONPREM | H5: OTHER | I5: OTHER | K5: Y | L5: unauthorized third-party activity in the Company's network; malware deployed | P5: https://www.sec.gov/Archives/edgar/data/1331875/000133187524000005/fnf-20231119.htm
A6: 5 | B6: MICROSOFT CORP | C6: 2024-01-19 | D6: 0001193125-24-011295 | E6: 1.05 | F6: Y | G6: UND | H6: OTHER | I6: OTHER | K6: Y | L6: nation-state actor accessed employee email accounts, later source code repositories; mail platform and entry method not stated | P6: https://www.sec.gov/Archives/edgar/data/789019/000119312524011295/d708866d8k.htm
A7: 6 | B7: Hewlett Packard Enterprise Co | C7: 2024-01-24 | D7: 0001645590-24-000009 | E7: 1.05 | F7: Y | G7: CLOUD | H7: OTHER | I7: OTHER | K7: Y | L7: unauthorized access to HPE's cloud-based email environment (Midnight Blizzard); entry method not stated | P7: https://www.sec.gov/Archives/edgar/data/1645590/000164559024000009/hpe-20240119.htm
A8: 7 | B8: SouthState Corp | C8: 2024-02-09 | D8: 0000950103-24-002017 | E8: 1.05 | F8: Y | G8: ONPREM | H8: OTHER | I8: OTHER | K8: Y | L8: isolated parts of its network to disrupt the unauthorized activity | P8: https://www.sec.gov/Archives/edgar/data/764038/000095010324002017/dp206600_8k.htm
A9: 8 | B9: WILLIS LEASE FINANCE CORP | C9: 2024-02-09 | D9: 0001018164-24-000005 | E9: 8.01 | F9: N | G9: UND | H9: OTHER | I9: OTHER | K9: Y | L9: unauthorized activity on portions of IT systems | P9: https://www.sec.gov/Archives/edgar/data/1018164/000101816424000005/wlfc-20240209.htm
A10: 9 | B10: PRUDENTIAL FINANCIAL INC | C10: 2024-02-13 | D10: 0001193125-24-033753 | E10: 1.05 | F10: Y | G10: UND | H10: OTHER | I10: OTHER | K10: Y | L10: accessed administrative and user data and user accounts; method not stated | P10: https://www.sec.gov/Archives/edgar/data/1137774/000119312524033753/d770643d8k.htm
A11: 10 | B11: UNITEDHEALTH GROUP INC | C11: 2024-02-22 | D11: 0000731766-24-000045 | E11: 1.05 | F11: Y | G11: UND | H11: OTHER | I11: OTHER | K11: Y | L11: threat actor gained access to Change Healthcare IT systems; hosting and entry not stated | P11: https://www.sec.gov/Archives/edgar/data/731766/000073176624000045/unh-20240221.htm
A12: 11 | B12: Cencora, Inc. | C12: 2024-02-27 | D12: 0001104659-24-028288 | E12: 1.05 | F12: Y | G12: UND | H12: OTHER | I12: OTHER | K12: Y | L12: data exfiltrated from information systems | P12: https://www.sec.gov/Archives/edgar/data/1140859/000110465924028288/tm247267d1_8k.htm
A13: 12 | B13: Federal Home Loan Bank of New York | C13: 2024-03-01 | D13: 0001654954-24-002505 | E13: 1.05 | F13: Y | G13: UND | H13: THIRD_PARTY | I13: THIRD_PARTY | K13: Y | L13: a fourth-party vendor (vendor of a bank vendor) was compromised; bank systems not affected | P13: https://www.sec.gov/Archives/edgar/data/1329842/000165495424002505/fhlbny_8k.htm
A14: 13 | B14: MARINEMAX INC | C14: 2024-03-12 | D14: 0000950170-24-030041 | E14: 1.05 | F14: Y | G14: UND | H14: OTHER | I14: OTHER | K14: Y | L14: cybercrime organization accessed a portion of the information environment | P14: https://www.sec.gov/Archives/edgar/data/1057060/000095017024030041/hzo-20240310.htm
A15: 14 | B15: RADIANT LOGISTICS, INC | C15: 2024-03-20 | D15: 0000950170-24-033954 | E15: 1.05 | F15: Y | G15: ONPREM | H15: OTHER | I15: OTHER | K15: Y | L15: isolated Canadian operations from the rest of its network | P15: https://www.sec.gov/Archives/edgar/data/1171155/000095017024033954/rlgt-20240319.htm
A16: 15 | B16: B. Riley Financial, Inc. | C16: 2024-04-08 | D16: 0001213900-24-031252 | E16: 1.05 | F16: Y | G16: ONPREM | H16: OTHER | I16: OTHER | K16: Y | L16: unauthorized access to Targus file systems; interruption of the Targus network | P16: https://www.sec.gov/Archives/edgar/data/1464790/000121390024031252/ea0203500-8k_briley.htm
... A18: 17 | B18: Frontier Communications Parent, Inc. | C18: 2024-04-18 | D18: 0001193125-24-100764 | E18: 1.05 | F18: Y | G18: UND | H18: OTHER | I18: OTHER | K18: Y | L18: third party accessed portions of IT environment; cybercrime group | P18: https://www.sec.gov/Archives/edgar/data/20520/000119312524100764/d784189d8k.htm
A19: 18 | B19: DROPBOX, INC. | C19: 2024-05-01 | D19: 0001467623-24-000024 | E19: 1.05 | F19: Y | G19: CLOUD | H19: OTHER | I19: OTHER | K19: Y | L19: unauthorized access to the Dropbox Sign production environment (the hosted e-signature service), all users' data | O19: borderline: SaaS inferred from the service, not the word cloud | P19: https://www.sec.gov/Archives/edgar/data/1467623/000146762324000024/dbx-20240429.htm
A20: 19 | B20: BRANDYWINE REALTY TRUST | C20: 2024-05-07 | D20: 0001193125-24-133132 | E20: 1.05 | F20: Y | G20: ONPREM | H20: OTHER | I20: OTHER | K20: Y | L20: access and encryption on a portion of internal corporate IT systems | P20: https://www.sec.gov/Archives/edgar/data/790816/000119312524133132/d824906d8k.htm
A21: 20 | B21: DocGo Inc. | C21: 2024-05-07 | D21: 0001822359-24-000037 | E21: 8.01 | F21: N | G21: UND | H21: OTHER | I21: OTHER | K21: Y | L21: threat actor accessed health records in ambulance business | P21: https://www.sec.gov/Archives/edgar/data/1822359/000182235924000037/dcgo-20240507.htm
A22: 21 | B22: KEY TRONIC CORP | C22: 2024-05-10 | D22: 0000719733-24-000015 | E22: 1.05 | F22: Y | G22: UND | H22: OTHER | I22: OTHER | K22: Y | L22: unauthorized access to portions of IT systems | M22: 2300000 | N22: 2300000 | O22: plus ~$15M revenue not fulfilled in quarter | P22: https://www.sec.gov/Archives/edgar/data/719733/000071973324000015/ktcc-20240506.htm
A23: 22 | B23: KULICKE & SOFFA INDUSTRIES INC | C23: 2024-06-12 | D23: 0000056978-24-000075 | E23: 8.01 | F23: N | G23: ONPREM | H23: OTHER | I23: OTHER | K23: Y | L23: unauthorized access into its network and servers | P23: https://www.sec.gov/Archives/edgar/data/56978/000005697824000075/klic-20240528.htm
A24: 23 | B24: GLOBE LIFE INC. | C24: 2024-06-14 | D24: 0000320335-24-000029 | E24: 8.01 | F24: N | G24: UND | H24: OTHER | I24: OTHER | K24: Y | L24: filing text not captured beyond a reference to Item 1.05 | O24: text not captured; re-read needed | P24: https://www.sec.gov/Archives/edgar/data/320335/000032033524000029/gl-20240614.htm
A25: 24 | B25: PENSKE AUTOMOTIVE GROUP, INC. | C25: 2024-06-21 | D25: 0001019849-24-000089 | E25: 8.01 | F25: N | G25: UND | H25: THIRD_PARTY | I25: THIRD_PARTY | J25: CDK | K25: N | L25: CDK Global (DMS provider) incident; hosting not stated in this filing | P25: https://www.sec.gov/Archives/edgar/data/1019849/000101984924000089/pag-20240619.htm
A26: 25 | B26: SONIC AUTOMOTIVE INC | C26: 2024-06-21 | D26: 0001043509-24-000059 | E26: 8.01 | F26: Y | G26: CLOUD | H26: THIRD_PARTY | I26: THIRD_PARTY | J26: CDK | K26: Y | L26: dealer management system hosted by CDK, a third-party provider, disrupted by CDK incident | P26: https://www.sec.gov/Archives/edgar/data/1043509/000104350924000059/sah-20240619.htm
A27: 26 | B27: GROUP 1 AUTOMOTIVE INC | C27: 2024-06-24 | D27: 0001031203-24-000048 | E27: 8.01 | F27: N | G27: CLOUD | H27: THIRD_PARTY | I27: THIRD_PARTY | J27: CDK | K27: N | L27: CDK software-as-a-service platform disrupted by CDK incident | P27: https://www.sec.gov/Archives/edgar/data/1031203/000103120324000048/gpi-20240619.htm
A28: 27 | B28: LITHIA MOTORS INC | C28: 2024-06-24 | D28: 0001023128-24-000079 | E28: 8.01 | F28: N | G28: CLOUD | H28: THIRD_PARTY | I28: THIRD_PARTY | J28: CDK | K28: N | L28: CDK hosted dealer management system disrupted by CDK incident | P28: https://www.sec.gov/Archives/edgar/data/1023128/000102312824000079/lad-20240619.htm
A29: 28 | B29: Affirm Holdings, Inc. | C29: 2024-07-01 | D29: 0001820953-24-000027 | E29: 8.01 | F29: N | G29: UND | H29: THIRD_PARTY | I29: THIRD_PARTY | J29: EVOLVE | K29: Y | L29: card issuer Evolve Bank breached; Affirm systems not compromised | P29: https://www.sec.gov/Archives/edgar/data/1820953/000182095324000027/afrm-20240625.htm
A30: 29 | B30: Crimson Wine Group, Ltd | C30: 2024-07-05 | D30: 0001562151-24-000030 | E30: 8.01 | F30: Y | G30: UND | H30: OTHER | I30: OTHER | K30: Y | L30: third party accessed certain technology systems | P30: https://www.sec.gov/Archives/edgar/data/1562151/000156215124000030/cwgl-20240630.htm
A31: 30 | B31: AT&T INC. | C31: 2024-07-12 | D31: 0000732717-24-000046 | E31: 1.05 | F31: Y | G31: CLOUD | H31: OTHER | I31: OTHER | K31: Y | L31: threat actors accessed an AT&T workspace on a third-party cloud platform; method not stated | O31: press links this to the 2024 Snowflake customer campaign; not stated in filing | P31: https://www.sec.gov/Archives/edgar/data/732717/000073271724000046/t-20240506.htm
A32: 31 | B32: BASSETT FURNITURE INDUSTRIES INC | C32: 2024-07-15 | D32: 0001437749-24-022743 | E32: 1.05 | F32: Y | G32: UND | H32: OTHER | I32: OTHER | K32: Y | L32: threat actor encrypted some data files | P32: https://www.sec.gov/Archives/edgar/data/10329/000143774924022743/bset20240715_8k.htm
A33: 32 | B33: Cadre Holdings, Inc. | C33: 2024-07-19 | D33: 0001104659-24-081176 | E33: 8.01 | F33: N | G33: UND | H33: OTHER | I33: OTHER | K33: Y | L33: third party accessed certain technology systems | P33: https://www.sec.gov/Archives/edgar/data/1860543/000110465924081176/tm2419841d1_8k.htm
A34: 33 | B34: META MATERIALS INC. | C34: 2024-08-01 | D34: 0000950170-24-089345 | E34: 1.05 | F34: Y | G34: UND | H34: INSIDER | I34: INSIDER | K34: Y | L34: a former executive officer deliberately deactivated the company website | P34: https://www.sec.gov/Archives/edgar/data/1431959/000095017024089345/mmat-20240725.htm
A35: 34 | B35: ADT Inc. | C35: 2024-08-08 | D35: 0000950157-24-001064 | E35: 8.01 | F35: N | G35: UND | H35: OTHER | I35: OTHER | K35: Y | L35: unauthorized actors accessed databases containing customer order information | O35: first of two ADT incidents | P35: https://www.sec.gov/Archives/edgar/data/1703056/000095015724001064/form8k.htm
A36: 35 | B36: ADT Inc. | C36: 2024-10-07 | D36: 0001193125-24-233900 | E36: 8.01 | F36: N | G36: ONPREM | H36: THIRD_PARTY | I36: CREDENTIAL | K36: Y | L36: accessed ADT's network using compromised credentials obtained through a third-party business partner | O36: second ADT incident | P36: https://www.sec.gov/Archives/edgar/data/1703056/000119312524233900/d876174d8k.htm
A37: 36 | B37: MICROCHIP TECHNOLOGY INC | C37: 2024-08-20 | D37: 0000827054-24-000153 | E37: 8.01 | F37: N | G37: ONPREM | H37: OTHER | I37: OTHER | K37: Y | L37: unauthorized party disrupted use of certain servers | P37: https://www.sec.gov/Archives/edgar/data/827054/000082705424000153/mchp-20240820.htm
A38: 37 | B38: HALLIBURTON CO | C38: 2024-09-03 | D38: 0000045012-24-000052 | E38: 1.05 | F38: Y | G38: UND | H38: OTHER | I38: OTHER | K38: Y | L38: third party gained access to certain systems | P38: https://www.sec.gov/Archives/edgar/data/45012/000004501224000052/hal-20240830.htm
A39: 38 | B39: American Water Works Company, Inc. | C39: 2024-10-07 | D39: 0001193125-24-233300 | E39: 8.01 | F39: N | G39: ONPREM | H39: OTHER | I39: OTHER | K39: Y | L39: unauthorized activity within its computer networks and systems | P39: https://www.sec.gov/Archives/edgar/data/1410636/000119312524233300/d869346d8k.htm
A40: 39 | B40: HEALTHCARE SERVICES GROUP INC | C40: 2024-10-16 | D40: 0000731012-24-000134 | E40: 8.01 | F40: N | G40: UND | H40: OTHER | I40: OTHER | K40: Y | L40: unauthorized activity within some systems | P40: https://www.sec.gov/Archives/edgar/data/731012/000073101224000134/hcsg-20241009.htm
A41: 40 | B41: NEWPARK RESOURCES INC | C41: 2024-11-07 | D41: 0000071829-24-000111 | E41: 8.01 | F41: N | G41: ONPREM | H41: OTHER | I41: OTHER | K41: Y | L41: ransomware; third party accessed internal information systems | P41: https://www.sec.gov/Archives/edgar/data/71829/000007182924000111/nr-20241029.htm
...

Sheet Costs
A1: Company | B1: Environment | C1: Cost low (USD) | D1: Cost high (USD) | E1: Midpoint (USD) | F1: What the figure is
A2: =Incidents!B4 -> loanDepot, Inc. | B2: =Incidents!G4 -> UND | C2: =Incidents!M4 -> 12000000 | D2: =Incidents!N4 -> 17000000 | E2: =AVERAGE(C2:D2) -> 14500000 | F2: =Incidents!O4 -> Q1 2024 expenses net of insurance
A3: =Incidents!B22 -> KEY TRONIC CORP | B3: =Incidents!G22 -> UND | C3: =Incidents!M22 -> 2300000 | D3: =Incidents!N22 -> 2300000 | E3: =AVERAGE(C3:D3) -> 2300000 | F3: =Incidents!O22 -> plus ~$15M revenue not fulfilled in quarter
A4: =Incidents!B42 -> iLearningEngines, Inc. | B4: =Incidents!G42 -> ONPREM | C4: =Incidents!M42 -> 250000 | D4: =Incidents!N42 -> 250000 | E4: =AVERAGE(C4:D4) -> 250000 | F4: =Incidents!O42 -> misdirected wire, not recovered
A5: =Incidents!B47 -> NIOCORP DEVELOPMENTS LTD | B5: =Incidents!G47 -> UND | C5: =Incidents!M47 -> 500000 | D5: =Incidents!N47 -> 500000 | E5: =AVERAGE(C5:D5) -> 500000 | F5: =Incidents!O47 -> misdirected payments, recovery uncertain
A6: =Incidents!B53 -> Coinbase Global, Inc. | B6: =Incidents!G53 -> UND | C6: =Incidents!M53 -> 180000000 | D6: =Incidents!N53 -> 400000000 | E6: =AVERAGE(C6:D6) -> 290000000 | F6: =Incidents!O53 -> preliminary estimate, remediation and customer reimbursement
A7: =Incidents!B60 -> DATA I/O CORP | B7: =Incidents!G60 -> UND | C7: =Incidents!M60 -> 180000 | D7: =Incidents!N60 -> 180000 | E7: =AVERAGE(C7:D7) -> 180000 | F7: =Incidents!O60 -> Q3 2025 remediation expenses
A8: =Incidents!B69 -> Coupang, Inc. | B8: =Incidents!G69 -> UND | C8: =Incidents!M69 -> 1200000000 | D8: =Incidents!N69 -> 1200000000 | E8: =AVERAGE(C8:D8) -> 1200000000 | F8: =Incidents!O69 -> customer compensation vouchers (~1.685T won)
A9: Incidents with a dollar figure | C9: =COUNT(C2:C8) -> 7
A10: Of those, environment stated | C10: =COUNTIF(B2:B8,"<>UND") -> 1
A12: Figures are as disclosed and not comparable: remediation expenses, misdirected payments, a preliminary range and customer vouchers.

Sheet Calls to check
A1: Company | B1: Code assigned | C1: Why it is a judgment call | D1: Your decision
A2: Dropbox Sign | B2: CLOUD / OTHER | C2: Coded cloud because Dropbox Sign is a hosted service; the filing never says "cloud".
A3: SouthState | B3: ONPREM / OTHER | C3: Coded on-premises from "isolated parts of its network".
A4: Radiant Logistics | B4: ONPREM / OTHER | C4: Coded on-premises from "isolate its Canadian operations from the rest of its network".
A5: AT&T | B5: CLOUD / OTHER | C5: Cause left unknown. Press ties it to the Snowflake account breaches; the filing does not.
A6: Penske Automotive | B6: UND / THIRD_PARTY | C6: Unlike the other three CDK dealers, its filing does not say CDK's system was hosted.
A7: Globe Life | B7: UND / OTHER | C7: No readable incident text came through; filing should be re-read.
A9: Yellow cells: enter Keep, or the code you would assign instead.

Sheet Screening
A1: Accession | B1: Company | C1: File date | D1: Form | E1: Item | F1: Screening result
A2: 0001628280-24-014795 | B2: 3M CO (MMM) | C2: 2024-04-04 | D2: 8-K | E2: 8.01 | F2: excluded: not an incident disclosure (phrase appears in risk factors, or no incident text)
A3: 0000950170-25-084312 | B3: ACCO BRANDS Corp (ACCO) | C3: 2025-06-10 | D3: 8-K | E3: 8.01 | F3: excluded: not an incident disclosure (phrase appears in risk factors, or no incident text)
A4: 0001193125-25-021878 | B4: ACELYRIN, Inc. (SLRN) | C4: 2025-02-06 | D4: 8-K | E4: 8.01 | F4: excluded: not an incident disclosure (phrase appears in risk factors, or no incident text)
A5: 0000950157-24-001064 | B5: ADT Inc. (ADT) | C5: 2024-08-08 | D5: 8-K | E5: 8.01 | F5: incident (first filing)
A6: 0001193125-24-233900 | B6: ADT Inc. (ADT) | C6: 2024-10-07 | D6: 8-K | E6: 8.01 | F6: incident (first filing)
A7: 0001193125-25-163851 | B7: ADVANCE AUTO PARTS INC (AAP) | C7: 2025-07-24 | D7: 8-K | E7: 8.01 | F7: excluded: not an incident disclosure (phrase appears in risk factors, or no incident text)
A8: 0000004977-25-000128 | B8: AFLAC INC (AFL) | C8: 2025-06-20 | D8: 8-K | E8: 8.01 | F8: incident (first filing)
A9: 0000766421-25-000023 | B9: ALASKA AIR GROUP, INC. (ALK) | C9: 2025-06-27 | D9: 8-K | E9: 8.01 | F9: incident (first filing)
A10: 0001104659-25-010169 | B10: ALUMIS INC. (ALMS) | C10: 2025-02-06 | D10: 8-K | E10: 8.01 | F10: excluded: not an incident disclosure (phrase appears in risk factors, or no incident text)
A11: 0001193125-24-193425 | B11: AMERICAN SUPERCONDUCTOR CORP /DE/ (AMSC) | C11: 2024-08-05 | D11: 8-K | E11: 8.01 | F11: excluded: not an incident disclosure (phrase appears in risk factors, or no incident text)
A12: 0001193125-25-314153 | B12: AMERICAN SUPERCONDUCTOR CORP /DE/ (AMSC) | C12: 2025-12-10 | D12: 8-K | E12: 8.01 | F12: excluded: not an incident disclosure (phrase appears in risk factors, or no incident text)
... A207: 0001831631-24-000020 | B207: loanDepot, Inc. (LDI) | C207: 2024-02-27 | D207: 8-K/A | E207: 8.01 | F207: update of incident 3
